Parsing... [0.020s CPU, 0.017s wall-clock]
Normalizing task... [0.000s CPU, 0.001s wall-clock]
Instantiating...
Generating Datalog program... [0.020s CPU, 0.010s wall-clock]
Normalizing Datalog program...
Normalizing Datalog program: [0.000s CPU, 0.005s wall-clock]
Preparing model... [0.030s CPU, 0.031s wall-clock]
Generated 31 rules.
Computing model... [244.580s CPU, 244.573s wall-clock]
9678417 relevant atoms
46072 auxiliary atoms
9724489 final queue length
19351364 total queue pushes
Completing instantiation... Traceback (most recent call last):
  File "/home/asai/repos/downward/src/translate/translate.py", line 478, in pddl_to_sas
    reachable_action_params) = instantiate.explore(task)
  File "/home/asai/repos/downward/src/translate/instantiate.py", line 77, in explore
    return instantiate(task, model)
  File "/home/asai/repos/downward/src/translate/instantiate.py", line 57, in instantiate
    fluent_facts, type_to_objects)
MemoryError
Error in sys.excepthook:
Traceback (most recent call last):
  File "/usr/lib/python2.7/dist-packages/apport_python_hook.py", line 66, in apport_excepthook
    from apport.fileutils import likely_packaged, get_recent_crashes
  File "/usr/lib/python2.7/dist-packages/apport/__init__.py", line 1, in <module>
    from apport.report import Report
  File "/usr/lib/python2.7/dist-packages/apport/report.py", line 12, in <module>
    import subprocess, tempfile, os.path, urllib, re, pwd, grp, os
MemoryError

Original exception was:
Traceback (most recent call last):
  File "/home/asai/repos/downward/src/translate/translate.py", line 478, in pddl_to_sas
    reachable_action_params) = instantiate.explore(task)
  File "/home/asai/repos/downward/src/translate/instantiate.py", line 77, in explore
    return instantiate(task, model)
  File "/home/asai/repos/downward/src/translate/instantiate.py", line 57, in instantiate
    fluent_facts, type_to_objects)
MemoryError
